Traceback (most recent call last):
  File "C:\Users\pranj\OneDrive\Desktop\PycharmProjects\Datascience\venv\Lib\site-packages\jupyter_cache\executors\utils.py", line 58, in single_nb_execution
    executenb(
  File "C:\Users\pranj\OneDrive\Desktop\PycharmProjects\Datascience\venv\Lib\site-packages\nbclient\client.py", line 1319, in execute
    return NotebookClient(nb=nb, resources=resources, km=km, **kwargs).execute()
           ^^^^^^^^^^^^^^^^^^^^^^^^^^^^^^^^^^^^^^^^^^^^^^^^^^^^^^^^^^^^^^^^^^^^^
  File "C:\Users\pranj\OneDrive\Desktop\PycharmProjects\Datascience\venv\Lib\site-packages\jupyter_core\utils\__init__.py", line 165, in wrapped
    return loop.run_until_complete(inner)
           ^^^^^^^^^^^^^^^^^^^^^^^^^^^^^^
  File "C:\Users\pranj\AppData\Local\Programs\Python\Python311\Lib\asyncio\base_events.py", line 650, in run_until_complete
    return future.result()
           ^^^^^^^^^^^^^^^
  File "C:\Users\pranj\AppData\Local\Programs\Python\Python311\Lib\contextlib.py", line 222, in __aexit__
    await self.gen.athrow(typ, value, traceback)
  File "C:\Users\pranj\OneDrive\Desktop\PycharmProjects\Datascience\venv\Lib\site-packages\nbclient\client.py", line 654, in async_setup_kernel
    yield
  File "C:\Users\pranj\OneDrive\Desktop\PycharmProjects\Datascience\venv\Lib\site-packages\nbclient\client.py", line 709, in async_execute
    await self.async_execute_cell(
  File "C:\Users\pranj\OneDrive\Desktop\PycharmProjects\Datascience\venv\Lib\site-packages\nbclient\client.py", line 1062, in async_execute_cell
    await self._check_raise_for_error(cell, cell_index, exec_reply)
  File "C:\Users\pranj\OneDrive\Desktop\PycharmProjects\Datascience\venv\Lib\site-packages\nbclient\client.py", line 918, in _check_raise_for_error
    raise CellExecutionError.from_cell_and_msg(cell, exec_reply_content)
nbclient.exceptions.CellExecutionError: An error occurred while executing the following cell:
------------------
import dagshub
dagshub.init(repo_owner='pranjalm04', repo_name='Machine_learning_project', mlflow=True)
------------------

----- stderr -----
Response (422):
b'{"message":""}'
------------------

[1;31m---------------------------------------------------------------------------[0m
[1;31mRepoNotFoundError[0m                         Traceback (most recent call last)
File [1;32m~\OneDrive\Desktop\PycharmProjects\Datascience\venv\Lib\site-packages\dagshub\common\init.py:88[0m, in [0;36minit[1;34m(repo_name, repo_owner, url, root, host, mlflow, dvc, patch_mlflow)[0m
[0;32m     87[0m [38;5;28;01mtry[39;00m:
[1;32m---> 88[0m     [43mrepo_api[49m[38;5;241;43m.[39;49m[43mget_repo_info[49m[43m([49m[43m)[49m
[0;32m     89[0m [38;5;28;01mexcept[39;00m RepoNotFoundError:

File [1;32m~\OneDrive\Desktop\PycharmProjects\Datascience\venv\Lib\site-packages\dagshub\common\api\repo.py:83[0m, in [0;36mRepoAPI.get_repo_info[1;34m(self)[0m
[0;32m     82[0m [38;5;28;01mif[39;00m res[38;5;241m.[39mstatus_code [38;5;241m==[39m [38;5;241m404[39m:
[1;32m---> 83[0m     [38;5;28;01mraise[39;00m RepoNotFoundError([38;5;124mf[39m[38;5;124m"[39m[38;5;124mRepo [39m[38;5;132;01m{[39;00m[38;5;28mself[39m[38;5;241m.[39mrepo_url[38;5;132;01m}[39;00m[38;5;124m not found[39m[38;5;124m"[39m)
[0;32m     84[0m [38;5;28;01melif[39;00m res[38;5;241m.[39mstatus_code [38;5;241m>[39m[38;5;241m=[39m [38;5;241m400[39m:

[1;31mRepoNotFoundError[0m: Repo https://dagshub.com/pranjalm04/Machine_learning_project not found

During handling of the above exception, another exception occurred:

[1;31mRuntimeError[0m                              Traceback (most recent call last)
Cell [1;32mIn[5], line 2[0m
[0;32m      1[0m [38;5;28;01mimport[39;00m [38;5;21;01mdagshub[39;00m
[1;32m----> 2[0m [43mdagshub[49m[38;5;241;43m.[39;49m[43minit[49m[43m([49m[43mrepo_owner[49m[38;5;241;43m=[39;49m[38;5;124;43m'[39;49m[38;5;124;43mpranjalm04[39;49m[38;5;124;43m'[39;49m[43m,[49m[43m [49m[43mrepo_name[49m[38;5;241;43m=[39;49m[38;5;124;43m'[39;49m[38;5;124;43mMachine_learning_project[39;49m[38;5;124;43m'[39;49m[43m,[49m[43m [49m[43mmlflow[49m[38;5;241;43m=[39;49m[38;5;28;43;01mTrue[39;49;00m[43m)[49m

File [1;32m~\OneDrive\Desktop\PycharmProjects\Datascience\venv\Lib\site-packages\dagshub\common\init.py:91[0m, in [0;36minit[1;34m(repo_name, repo_owner, url, root, host, mlflow, dvc, patch_mlflow)[0m
[0;32m     89[0m [38;5;28;01mexcept[39;00m RepoNotFoundError:
[0;32m     90[0m     log_message([38;5;124mf[39m[38;5;124m"[39m[38;5;124mRepository [39m[38;5;132;01m{[39;00mrepo_name[38;5;132;01m}[39;00m[38;5;124m doesn[39m[38;5;124m'[39m[38;5;124mt exist, creating it under current user.[39m[38;5;124m"[39m)
[1;32m---> 91[0m     [43mcreate_repo[49m[43m([49m[43mrepo_name[49m[43m)[49m
[0;32m     93[0m [38;5;66;03m# Get the token for the configs[39;00m
[0;32m     94[0m token [38;5;241m=[39m get_token(host[38;5;241m=[39mhost)

File [1;32m~\OneDrive\Desktop\PycharmProjects\Datascience\venv\Lib\site-packages\dagshub\upload\wrapper.py:165[0m, in [0;36mcreate_repo[1;34m(repo_name, org_name, description, private, auto_init, gitignores, license, readme, template, host)[0m
[0;32m    163[0m logger[38;5;241m.[39merror([38;5;124mf[39m[38;5;124m"[39m[38;5;124mResponse ([39m[38;5;132;01m{[39;00mres[38;5;241m.[39mstatus_code[38;5;132;01m}[39;00m[38;5;124m):[39m[38;5;130;01m\n[39;00m[38;5;124m"[39m [38;5;124mf[39m[38;5;124m"[39m[38;5;132;01m{[39;00mres[38;5;241m.[39mcontent[38;5;132;01m}[39;00m[38;5;124m"[39m)
[0;32m    164[0m [38;5;28;01mif[39;00m res[38;5;241m.[39mstatus_code [38;5;241m==[39m HTTPStatus[38;5;241m.[39mUNPROCESSABLE_ENTITY:
[1;32m--> 165[0m     [38;5;28;01mraise[39;00m [38;5;167;01mRuntimeError[39;00m([38;5;124m"[39m[38;5;124mRepository name is invalid or it already exists.[39m[38;5;124m"[39m)
[0;32m    166[0m [38;5;28;01melse[39;00m:
[0;32m    167[0m     [38;5;28;01mraise[39;00m [38;5;167;01mRuntimeError[39;00m([38;5;124m"[39m[38;5;124mFailed to create the desired repository.[39m[38;5;124m"[39m)

[1;31mRuntimeError[0m: Repository name is invalid or it already exists.

